Workbook

Sheet Diagrama ER (corregido)

Sheet Inventario Modelo Lógico (corre
A1: Tablas resultantes del Diccionario Genérico (Modelo Lógico)
A2: # | B2: Tabla | C2: Descripción Tabla | D2: Observaciones
A3: 1 | B3: usuario | C3: Persona registrada en la plataforma que interactúa con la red social. | D3: Origen: Entidad Usuario | PK: id_usuario | FK: id_rol, id_tipo_usuario | UK: nombre_usuario, correo
A4: =A3+1 -> 2 | B4: rol | C4: Clasifica a los usuarios según sus permisos y nivel de acceso dentro del sistema. | D4: Origen: Entidad Rol | PK: id_rol | UK: nombre_rol
A5: =A4+1 -> 3 | B5: tipo_usuario | C5: Clasificación académica o profesional del usuario con fines estadísticos. | D5: Origen: Entidad TipoUsuario | PK: id_tipo_usuario | UK: nombre_tipo
A6: =A5+1 -> 4 | B6: perfil | C6: Extensión de la información del usuario que almacena intereses, habilidades y datos adicionales en formato JSONB. | D6: Origen: Entidad Perfil (débil) | PK: id_perfil | FK: id_usuario | UK: id_usuario
A7: =A6+1 -> 5 | B7: interes | C7: Catálogo de intereses personales (fotografía, videojuegos, lectura, etc.) que los usuarios pueden asociar a su cuenta. | D7: Origen: Entidad Interes | PK: id_interes | UK: nombre_interes
A8: =A7+1 -> 6 | B8: habilidad | C8: Catálogo de habilidades (programación, diseño gráfico, etc.) que los usuarios pueden declarar en su cuenta. | D8: Origen: Entidad Habilidad | PK: id_habilidad | UK: nombre_habilidad
A9: =A8+1 -> 7 | B9: publicacion | C9: Contenido compartido por un usuario en el muro de la red social. | D9: Origen: Entidad Publicacion | PK: id_publicacion | FK: id_usuario
A10: =A9+1 -> 8 | B10: comentario | C10: Respuesta o reacción escrita que un usuario realiza sobre una publicación específica. | D10: Origen: Entidad Comentario (débil) | PK: id_comentario | FK: id_publicacion, id_usuario, id_comentario_padre
A11: =A10+1 -> 9 | B11: grupo | C11: Espacio colaborativo creado para reunir usuarios con intereses académicos, deportivos o de ocio en común. | D11: Origen: Entidad Grupo | PK: id_grupo | FK: id_usuario_creador
A12: =A11+1 -> 10 | B12: tipo_servicio | C12: Catálogo predefinido que clasifica los servicios ofrecidos (tutorías, reparaciones, asesorías, etc.). | D12: Origen: Entidad TipoServicio | PK: id_tipo_servicio | UK: nombre_tipo
A13: =A12+1 -> 11 | B13: servicio | C13: Oferta concreta que un usuario publica para brindar un servicio a otros, con precio y descripción. | D13: Origen: Entidad Servicio | PK: id_servicio | FK: id_tipo_servicio, id_usuario
A14: =A13+1 -> 12 | B14: tipo_producto | C14: Catálogo predefinido que clasifica los productos en venta (libros, tecnología, ropa, etc.). | D14: Origen: Entidad TipoProducto | PK: id_tipo_producto | UK: nombre_tipo
A15: =A14+1 -> 13 | B15: producto | C15: Artículo físico o digital que un usuario publica para vender o adquirir dentro de la plataforma. | D15: Origen: Entidad Producto | PK: id_producto | FK: id_tipo_producto, id_usuario
... A33: =A32+1 -> 31 | B33: venta_evento | C33: Detalle de los eventos incluidos en cada venta (por ejemplo, entradas), con la cantidad y el precio unitario. | D33: Origen: Relación M:N Venta — incluye — Evento | PK: id_venta_evento | FK: id_venta, id_evento | UK compuesta: (id_venta, id_evento)

Sheet Tipos de Dato
A1: Tipos de Datos - Tabla Comparativa
A2: # | B2: Tipo de Dato Genérico | C2: Tipos de Dato - PosgreSQL | D2: DOMINIO | E2: BYTES | F2: Observaciones
A3: 1 | B3: AUTOINCREMENTABLE | C3: SERIAL (equivale a INTEGER con secuencia; alternativa: INTEGER GENERATED ALWAYS AS IDENTITY) | D3: 1 a 2,147,483,647 | E3: 4 | F3: Usado en todas las llaves primarias. Si se espera más de 2 mil millones de filas se usa BIGSERIAL (8 bytes).
A4: =A3+1 -> 2 | B4: UUID | C4: UUID | D4: Se representa como una cadena de 32 dígitos hexadecimales | E4: 16 | F4: Identificador universal. No se usa en este modelo; se deja como referencia.
A5: =A4+1 -> 3 | B5: ENTERO | C5: INTEGER | D5: -2,147,483,648 a +2,147,483,647 | E5: 4 | F5: Llaves foráneas y cantidades. Alternativas: SMALLINT (2 bytes) y BIGINT (8 bytes). En PostgreSQL el INTEGER no usa ancho de visualización; el tamaño 11 del diccionario se conserva de la tarea 2.
A6: =A5+1 -> 4 | B6: DECIMAL | C6: NUMERIC(p,s) | D6: NUMERIC(4,2) 2 dígitos 2 dígitos -99.99 a +99.99 NUMERIC(6,0) 6 dígitos 0 dígitos -999,999 a +999,999 NUMERIC(5,4) 1 dígito 4 dígitos -9.9999 a +9.9999 | E6: Variable (2 bytes por cada 4 dígitos + cabecera de 5 a 8 bytes) | F6: Valores monetarios exactos. Se usa NUMERIC(10,2) en precio, precio_unitario y total.
A7: =A6+1 -> 5 | B7: LÓGICO | C7: BOOLEAN | D7: 't' (o TRUE)/ 'f' (o FALSE) | E7: 1 | F7: Valores TRUE / FALSE. Usado en notificacion.leida.
A8: =A7+1 -> 6 | B8: TEXTO | C8: TEXT | D8: Hasta 1 GB | E8: Variable (1 o 4 bytes de cabecera + contenido) | F8: Texto sin límite de longitud. En este modelo los textos largos se limitan con VARCHAR(n) para conservar el tamaño definido en la tarea 2.
A9: =A8+1 -> 7 | B9: CARACTER | C9: CHAR(n) | D9: Exactamente n caracteres | E9: n (+ 1 byte de cabecera) | F9: Cadena de longitud fija, rellena con espacios. No se usa en este modelo.
A10: =A9+1 -> 8 | B10: FECHA | C10: DATE | D10: • Límite inferior: 4713 a. C. (Antes de Cristo / BC) • Límite superior: 5,874,897 d. C. (Después de Cristo / AD) | E10: 4 | F10: Solo fecha. Usado en evento.fecha.
A11: =A10+1 -> 9 | B11: FECHA_HORA | C11: TIMESTAMP | D11: • Límite Inferior: 4713 a. C. • Límite Superior: 294,276 d. C. • Precisión por defecto: 6 dígitos en los microsegundos. | E11: 8 | F11: Fecha y hora sin zona horaria. Usado en fechas de publicación, comentario, mensaje, venta, etc. Para solo hora se usa TIME (8 bytes), como en evento.hora.
A12: =A11+1 -> 10 | B12: IMAGEN | C12: BYTEA | D12: Límite Máximo Absoluto: Puede almacenar cadenas binarias de hasta 1 Gigabyte (GB) por celda. | E12: Variable (1 o 4 bytes de cabecera + contenido) | F12: No se usa: las imágenes se almacenan como URL (VARCHAR) y no como binario dentro de la base.
A13: =A12+1 -> 11 | B13: AUDIO | C13: BYTEA | D13: Límite Máximo Absoluto: Puede almacenar cadenas binarias de hasta 1 Gigabyte (GB) por celda. | E13: Variable (1 o 4 bytes de cabecera + contenido) | F13: No se usa en este modelo; los archivos de audio se referenciarían por URL.
A14: =A13+1 -> 12 | B14: URL | C14: VARCHAR(255) | D14: 255 caracteres. | E14: Variable (1 o 4 bytes de cabecera + longitud real) | F14: Usado en foto_perfil_url y contenido_multimedia.
A15: =A14+1 -> 13 | B15: ENUM | C15: CREATE TYPE … AS ENUM (…) | D15: el conjunto exacto de las etiquetas de texto que escribiste entre comillas dentro de los paréntesis durante su creación, más el valor NULL (a menos que se restrinja). | E15: 4 | F15: No se usa; el dominio de estado_publicacion (PUBLICADO, OCULTO, ELIMINADO) se define con VARCHAR(20) como en la tarea 2.
... A18: =A17+1 -> 16 | B18: JSON | C18: JSONB | D18: Límite Máximo Absoluto: puede pesar hasta 1 Gigabyte (GB) en su representación binaria. | E18: Variable (según el contenido) | F18: Datos semiestructurados indexables. No se usa en las tablas finales; JSON guarda el texto tal cual y JSONB lo almacena en binario.

Sheet DICCIONARIO DATOS (Físico)
A1: DICCIONARIO DE DATOS FÍSICO (PostgreSQL)
A2: Inventario de Tablas
A3: # | B3: Tabla | F3: Descripción Tabla | X3: Observaciones
A4: 1 | B4: ='Inventario Modelo Lógico (corre'!B3 -> usuario | F4: ='Inventario Modelo Lógico (corre'!C3 -> Persona registrada en la plataforma que interactúa con la red social. | X4: ='Inventario Modelo Lógico (corre'!D3 -> Origen: Entidad Usuario | PK: id_usuario | FK: id_rol, id_tipo_usuario | UK: nombre_usuario, correo
A5: =A4+1 -> 2 | B5: ='Inventario Modelo Lógico (corre'!B4 -> rol | F5: ='Inventario Modelo Lógico (corre'!C4 -> Clasifica a los usuarios según sus permisos y nivel de acceso dentro del sistema. | X5: ='Inventario Modelo Lógico (corre'!D4 -> Origen: Entidad Rol | PK: id_rol | UK: nombre_rol
A6: =A5+1 -> 3 | B6: ='Inventario Modelo Lógico (corre'!B5 -> tipo_usuario | F6: ='Inventario Modelo Lógico (corre'!C5 -> Clasificación académica o profesional del usuario con fines estadísticos. | X6: ='Inventario Modelo Lógico (corre'!D5 -> Origen: Entidad TipoUsuario | PK: id_tipo_usuario | UK: nombre_tipo
A7: =A6+1 -> 4 | B7: ='Inventario Modelo Lógico (corre'!B6 -> perfil | F7: ='Inventario Modelo Lógico (corre'!C6 -> Extensión de la información del usuario que almacena intereses, habilidades y datos adicionales en formato JSONB. | X7: ='Inventario Modelo Lógico (corre'!D6 -> Origen: Entidad Perfil (débil) | PK: id_perfil | FK: id_usuario | UK: id_usuario
A8: =A7+1 -> 5 | B8: ='Inventario Modelo Lógico (corre'!B7 -> interes | F8: ='Inventario Modelo Lógico (corre'!C7 -> Catálogo de intereses personales (fotografía, videojuegos, lectura, etc.) que los usuarios pueden asociar a su cuenta. | X8: ='Inventario Modelo Lógico (corre'!D7 -> Origen: Entidad Interes | PK: id_interes | UK: nombre_interes
A9: =A8+1 -> 6 | B9: ='Inventario Modelo Lógico (corre'!B8 -> habilidad | F9: ='Inventario Modelo Lógico (corre'!C8 -> Catálogo de habilidades (programación, diseño gráfico, etc.) que los usuarios pueden declarar en su cuenta. | X9: ='Inventario Modelo Lógico (corre'!D8 -> Origen: Entidad Habilidad | PK: id_habilidad | UK: nombre_habilidad
A10: =A9+1 -> 7 | B10: ='Inventario Modelo Lógico (corre'!B9 -> publicacion | F10: ='Inventario Modelo Lógico (corre'!C9 -> Contenido compartido por un usuario en el muro de la red social. | X10: ='Inventario Modelo Lógico (corre'!D9 -> Origen: Entidad Publicacion | PK: id_publicacion | FK: id_usuario
A11: =A10+1 -> 8 | B11: ='Inventario Modelo Lógico (corre'!B10 -> comentario | F11: ='Inventario Modelo Lógico (corre'!C10 -> Respuesta o reacción escrita que un usuario realiza sobre una publicación específica. | X11: ='Inventario Modelo Lógico (corre'!D10 -> Origen: Entidad Comentario (débil) | PK: id_comentario | FK: id_publicacion, id_usuario, id_comentario_padre
A12: =A11+1 -> 9 | B12: ='Inventario Modelo Lógico (corre'!B11 -> grupo | F12: ='Inventario Modelo Lógico (corre'!C11 -> Espacio colaborativo creado para reunir usuarios con intereses académicos, deportivos o de ocio en común. | X12: ='Inventario Modelo Lógico (corre'!D11 -> Origen: Entidad Grupo | PK: id_grupo | FK: id_usuario_creador
A13: =A12+1 -> 10 | B13: ='Inventario Modelo Lógico (corre'!B12 -> tipo_servicio | F13: ='Inventario Modelo Lógico (corre'!C12 -> Catálogo predefinido que clasifica los servicios ofrecidos (tutorías, reparaciones, asesorías, etc.). | X13: ='Inventario Modelo Lógico (corre'!D12 -> Origen: Entidad TipoServicio | PK: id_tipo_servicio | UK: nombre_tipo
A14: =A13+1 -> 11 | B14: ='Inventario Modelo Lógico (corre'!B13 -> servicio | F14: ='Inventario Modelo Lógico (corre'!C13 -> Oferta concreta que un usuario publica para brindar un servicio a otros, con precio y descripción. | X14: ='Inventario Modelo Lógico (corre'!D13 -> Origen: Entidad Servicio | PK: id_servicio | FK: id_tipo_servicio, id_usuario
A15: =A14+1 -> 12 | B15: ='Inventario Modelo Lógico (corre'!B14 -> tipo_producto | F15: ='Inventario Modelo Lógico (corre'!C14 -> Catálogo predefinido que clasifica los productos en venta (libros, tecnología, ropa, etc.). | X15: ='Inventario Modelo Lógico (corre'!D14 -> Origen: Entidad TipoProducto | PK: id_tipo_producto | UK: nombre_tipo
A16: =A15+1 -> 13 | B16: ='Inventario Modelo Lógico (corre'!B15 -> producto | F16: ='Inventario Modelo Lógico (corre'!C15 -> Artículo físico o digital que un usuario publica para vender o adquirir dentro de la plataforma. | X16: ='Inventario Modelo Lógico (corre'!D15 -> Origen: Entidad Producto | PK: id_producto | FK: id_tipo_producto, id_usuario
... A34: =A33+1 -> 31 | B34: ='Inventario Modelo Lógico (corre'!B33 -> venta_evento | F34: ='Inventario Modelo Lógico (corre'!C33 -> Detalle de los eventos incluidos en cada venta (por ejemplo, entradas), con la cantidad y el precio unitario. | X34: ='Inventario Modelo Lógico (corre'!D33 -> Origen: Relación M:N Venta — incluye — Evento | PK: id_venta_evento | FK: id_venta, id_evento | UK compuesta: (id_venta, id_evento)
A36: Tablas en Detalle
A38: 1 | B38: Tabla | C38: =B4 -> usuario | G38: Descripción Tabla | K38: =F4 -> Persona registrada en la plataforma que interactúa con la red social. | X38: Versión | Y38: 1.0
A39: # | B39: Campo | C39: Descripción Campo | G39: Tipo Dato (PostgreSQL) | K39: Tamaño / Longitud | O39: Nulo | R39: PK | T39: FK | V39: UK | X39: Nota/Comentarios
A40: 1 | B40: id_usuario | C40: Identificador numérico único y autoincrementable que distingue a cada usuario dentro del sistema. Es la llave primaria de la tabla. | G40: SERIAL | K40: 11 | O40: No | R40: S
A41: 2 | B41: id_rol | C41: Llave foránea que enlaza al usuario con el rol que determina sus permisos dentro del sistema. | G41: INTEGER | K41: 11 | O41: No | T41: S | X41: FK → rol(id_rol).
A42: 3 | B42: id_tipo_usuario | C42: Llave foránea que enlaza al usuario con su clasificación académica o profesional. | G42: INTEGER | K42: 11 | O42: No | T42: S | X42: FK → tipo_usuario(id_tipo_usuario).
A43: 4 | B43: nombre_completo | C43: Nombres y apellidos reales de la persona, utilizados para identificación personal en el perfil y en la interfaz de la red social. | G43: VARCHAR | K43: 80 | O43: No
A44: 5 | B44: nombre_usuario | C44: Alias público único (handle) que el usuario elige para ser identificado, mencionado y etiquetado dentro de la Red Social. | G44: VARCHAR | K44: 50 | O44: No | V44: S
A45: 6 | B45: correo | C45: Dirección de correo electrónico única asociada a la cuenta, utilizada como medio de contacto, recuperación de contraseña y para iniciar sesión en la plataforma. | G45: VARCHAR | K45: 100 | O45: No | V45: S
A46: 7 | B46: contraseña | C46: Clave de acceso personal del usuario; se almacena encriptada (hash) por motivos de seguridad y es obligatoria para la autenticación en el sistema. | G46: VARCHAR | K46: 50 | O46: No | X46: Se almacena cifrada (hash), nunca en texto plano.
A48: N
A49: NOTA: En las columnas PK, FK y UK debe colocar “S” solamente cuando aplique. En la columna “Nulo” coloque “No” en caso de que el campo debe estar valorizado
A51: 2 | B51: Tabla | C51: =B5 -> rol | G51: Descripción Tabla | K51: =F5 -> Clasifica a los usuarios según sus permisos y nivel de acceso dentro del sistema. | X51: Versión | Y51: 1.0
A52: # | B52: Campo | C52: Descripción Campo | G52: Tipo Dato (PostgreSQL) | K52: Tamaño / Longitud | O52: Nulo | R52: PK | T52: FK | V52: UK | X52: Nota/Comentarios
A53: 1 | B53: id_rol | C53: Identificador numérico único que distingue a cada tipo de rol dentro del sistema. Es la llave primaria de la tabla y se utiliza para referenciar el nivel de permisos de un usuario. | G53: SERIAL | K53: 11 | O53: No | R53: S
A54: 2 | B54: nombre_rol | C54: Nombre corto y único que identifica al rol (Administrador, Auxiliar, Miembro o Visitante). Sirve para clasificar rápidamente el nivel de acceso y responsabilidad en la plataforma. | G54: VARCHAR | K54: 30 | O54: No | V54: S
A55: 3 | B55: descripcion | C55: Texto explicativo que detalla las funciones, permisos y alcance de las acciones que puede realizar un usuario asignado a ese rol dentro de la Red Social. | G55: VARCHAR | K55: 255 | O55: Sí
A57: N
A59: 3 | B59: Tabla | C59: =B6 -> tipo_usuario | G59: Descripción Tabla | K59: =F6 -> Clasificación académica o profesional del usuario con fines estadísticos. | X59: Versión | Y59: 1.0
A60: # | B60: Campo | C60: Descripción Campo | G60: Tipo Dato (PostgreSQL) | K60: Tamaño / Longitud | O60: Nulo | R60: PK | T60: FK | V60: UK | X60: Nota/Comentarios
A61: 1 | B61: id_tipo_usuario | C61: Identificador numérico único para cada clasificación de usuario. | G61: SERIAL | K61: 11 | O61: No | R61: S
A62: 2 | B62: nombre_tipo | C62: Nombre corto de la clasificación (ej. "Estudiante", "Egresado"). Es único para evitar duplicados. | G62: VARCHAR | K62: 50 | O62: No | V62: S
A63: 3 | B63: descripcion | C63: Breve explicación de a quién pertenece ese tipo de usuario y su propósito en la red (ej. "Usuario activo de pregrado"). | G63: VARCHAR | K63: 255 | O63: Sí
...
